Workbook

Sheet Face B (2)
A2: MAHARASTRA INDUSTRIAL DEVELOPMENT CORPORATION
A3: ( A Government of Maharashtra Undertaking )
A6: NAME OF WORK :- | E6: M&R TO W/S/S AT NAGOTHANE INDUSTRIAL AREA… REPAIRING & PAITING OF STAFF QUARTERS IN WTP COLONY AT NAGOTHANE
B8: ESTIMATED COST :-
E9: REPAIRING & PAITING OF STAFF QUARTERS IN WTP COLONY AT NAGOTHANE | H9: ='Painting Estimate Colony F'!K503 -> 4854364.4
G11: Total Rs. | H11: =SUM(H9:H10) -> 4854364.4
B13: ADD 5% CONTINGENCIES :- | G13: Rs. | H13: =H11*5/100 -> 242718.22
G15: Total Rs. | H15: =SUM(H11:H14) -> 5097082.6 | J15: NET
G18: Say Rs. | H18: =ROUNDUP(H15,-2) -> 5097100 | J18: (NET)
H25: Deputy Engineer,
H26: M.I.D.C. Sub-Division
H27: ALIBAG
A48: MAHARASTRA INDUSTRIAL DEVELOPMENT CORPORATION
A49: ( A Government of Maharashtra Undertaking )
B51: NAME OF WORK :- | E51: M & R to Roads in Patalganga Industrial Area….
E52: ='[1]Measu Premonsoon'!#REF! -> #REF!
E54: Attending pre-monsoon and during monsoon work, cleaning of road side built-up gutters, C. D. works etc.
B60: ESTIMATED COST :-
F62: Rs. | G62: ='[1]Abstr Premonsoon '!H1461 -> #REF!
B64: ADD 5% CONTINGENCIES :- | F64: Rs. | G64: =G62*0.05 -> #REF!
E67: Total | F67: Rs. | G67: =SUM(G62:G66) -> #REF!
E69: SAY | F69: Rs. | G69: 10,45,93,200.00 | H69: (Net)
G76: Deputy Engineer,
G77: M.I.D.C. Sub-Division
G78: PATALGANGA
A104: MAHARASTRA INDUSTRIAL DEVELOPMENT CORPORATION
A105: ( A Government of Maharashtra Undertaking )
B109: NAME OF WORK :- | E109: Patalganga Indl.Area....M & R to W/ S/ Scheme .. Providing & fixing 7 rows G.I. barbed wire fencing around Old pure water sump at 54.00 MLD WTP.
E110: Attending pre-monsoon and during monsoon work, cleaning of road side built-up gutters, C. D. works etc.
B115: ABSTRACT
B117: ESTIMATED COST :-
B119: Providing & fixing 7 rows G.I. barbed wire fencing around Old pure water sump at 54.00 MLD WTP. | F119: Rs. | G119: 47576.25
E121: Total | F121: Rs. | G121: =SUM(G119:G120) -> 47576.25
B122: ADD 5% CONTINGENCIES :- | F122: Rs. | G122: =+G121*0.05 -> 2378.8125
E125: Total | F125: Rs. | G125: =+G121+G122 -> 49955.062
E127: SAY | F127: Rs. | G127: 49960 | H127: (Net)
G132: Deputy Engineer,
G133: M.I.D.C. Sub-Division
G134: PATALGANGA
A163: MAHARASTRA INDUSTRIAL DEVELOPMENT CORPORATION
...

Sheet Face F
A2: MAHARASTRA INDUSTRIAL DEVELOPMENT CORPORATION
A3: ( A Government of Maharashtra Undertaking )
A5: ESTIMATE
B8: NAME OF WORK :- | E8: ='Face B (2)'!E6:K6 -> M&R TO W/S/S AT NAGOTHANE INDUSTRIAL AREA… REPAIRING & PAITING OF STAFF QUARTERS IN WTP COLONY AT NAGOTHANE
E9: Patalganga Indl. Area… Development of plot & premices @ newly constructed Jack-Well..
B10: ESTIMATED COST :- | E10: Net :- | F10: Rs. | G10: ='Face B (2)'!H18 -> 5097100 | H10: ( NET )
E12: Gross :- | F12: Rs.
B15: REFERANCE TO ADMINISTRATIVE
B16: APPROVAL
B19: TECHNICAL SANCTION :- | E19: For Rs. | F19: ………………………………. ( Net)
E20: Granted by……………………………. …. vide
E21: his register item No……………………………
E22: for the month of ………………………………
B25: ESTIMATE PREPARED BY :- | E25: Name and Designation : - Alat A A Assistant Engineer
E26: Signature ………………………………………..
B28: ESTIMATE CHECKED BY :- | E28: Name and Designation :- S.A.Kumbhar | H28: Asstt. Engineer,
E29: Signature ……………………………………..
E35: Deputy Engineer
E39: Executive Engineer
E44: Suprintending Engineer
E49: Chief Engineer

Sheet meas Colony 20.05.15
A1: M E A S U R E M E N T S
A3: Name of Work :- | C3: M&R TO W/S/S AT NAGOTHANE INDUSTRIAL AREA… REPAIRING & PAITING OF STAFF QUARTERS IN WTP COLONY AT NAGOTHANE
A6: Name of Work :- | C6: M&R TO W/S/S AT NAGOTHANE INDUSTRIAL AREA... REPAIRING & PAINTING OF STAFF QUARTERS IN WTP COLONY AT NAGOTHANE
A9: Item No. | B9: Ref.to CSR | C9: Description of Item | D9: No. | E9: Length | F9: Breath | G9: Depth | H9: Quantity | I9: Unit | J9: Rate | K9: Amount
A10: 1 | B10: Gen/A/10 | C10: Open excavation for road works, side gutters
C11: For Plinth Protection Class III L/S & S/S | D11: 2 | E11: 16 | F11: 1.5 | G11: 0.5 | H11: =D11*E11*F11*G11 -> 24 | I11: m³
D12: 2 | E12: 15.5 | F12: 1.5 | G12: 0.5 | H12: =D12*E12*F12*G12 -> 23.25 | I12: m³
C13: Add extra for front side | D13: 2 | E13: 3 | F13: 1.5 | G13: 0.5 | H13: =D13*E13*F13*G13 -> 4.5 | I13: m³
C14: For Plinth Protection Class IV L/S & S/S | D14: 2 | E14: 21 | F14: 1.5 | G14: 0.5 | H14: =D14*E14*F14*G14 -> 31.5 | I14: m³
D15: 2 | E15: 7.5 | F15: 1.5 | G15: 0.5 | H15: =D15*E15*F15*G15 -> 11.25 | I15: m³
C16: Add extra for front side | D16: 2 | E16: 3 | F16: 1.5 | G16: 0.5 | H16: =D16*E16*F16*G16 -> 4.5 | I16: m³
I17: m³
F18: Total | H18: =SUM(H11:H16) -> 99 | I18: m³
F19: Say | H19: =ROUNDUP(H18,0) -> 99 | I19: m³ | J19: 150 | K19: =J19*H19 -> 14850
A21: 2 | B21: Gen/B/7 | C21: Removing tiled flooring in all types of tiling or flooring i.e. Shahabad, Kotah, Cement, ….. with all leads & lifts.
C22: For Plinth Protection Class III L/S & S/S | D22: 2 | E22: 16 | F22: 1.5 | H22: =F22*E22*D22 -> 48 | I22: m³
D23: 2 | E23: 15.5 | F23: 1.5 | H23: =F23*E23*D23 -> 46.5 | I23: m³
C24: For Plinth Protection Class IV L/S & S/S | D24: 2 | E24: 21 | F24: 1.5 | H24: =D24*E24*F24 -> 63 | I24: m²
D25: 2 | E25: 7.5 | F25: 1.5 | H25: =D25*E25*F25 -> 22.5 | I25: m²
C27: Flooring
C28: Class III (Internal)
C29: Living Room | D29: 8 | E29: 3.05 | F29: 3.6 | H29: =F29*E29*D29 -> 87.84 | I29: m²
C30: Skirting | D30: 8 | E30: 3.05 | F30: 3.6 | G30: 0.1 | H30: =F30*E30*D30*G30 -> 8.784 | I30: m²
C31: Bed Room | D31: 8 | E31: 3.05 | F31: 3.05 | H31: =F31*E31*D31 -> 74.42 | I31: m²
C32: Skirting | D32: 8 | E32: 3.05 | F32: 3.05 | G32: 0.1 | H32: =F32*E32*D32*G32 -> 7.442 | I32: m²
C33: Kit.Room | D33: 8 | E33: 3.05 | F33: 2.12 | H33: =F33*E33*D33 -> 51.728 | I33: m²
C34: Skirting | D34: 8 | E34: 3.05 | F34: 2.12 | G34: 0.1 | H34: =F34*E34*D34*G34 -> 5.1728 | I34: m²
C35: Bath | D35: 8 | E35: 1.9 | F35: 1.07 | H35: =F35*E35*D35 -> 16.264 | I35: m²
C36: Removing Dado | D36: 8 | E36: 1.9 | F36: 1.07 | G36: 1.5 | H36: =F36*E36*D36*G36 -> 24.396 | I36: m²
C37: W.C. | D37: 8 | E37: 1.08 | F37: 0.95 | H37: =F37*E37*D37 -> 8.208 | I37: m²
C38: Removing Dado | D38: 8 | E38: 1.08 | F38: 0.95 | G38: 1.5 | H38: =F38*E38*D38*G38 -> 12.312 | I38: m²
C39: Passage | D39: 8 | E39: 3.05 | F39: 2.14 | H39: =F39*E39*D39 -> 52.216 | I39: m²
C40: Comman Passage @ Ground | D40: 1 | E40: 5.1 | F40: 2.15 | H40: =F40*E40*D40 -> 10.965 | I40: m²
C41: Comman Passage @ Ist Floor & IInd Floor | D41: 2 | E41: 2.5 | F41: 2.15 | H41: =F41*E41*D41 -> 10.75 | I41: m²
C42: Staircsae Head Room Slab | D42: 1 | E42: 5.2 | F42: 2.15 | H42: =F42*E42*D42 -> 11.18 | I42: m²
C43: Mid Landing | D43: 2 | E43: 2.15 | F43: 1.2 | H43: =F43*E43*D43 -> 5.16 | I43: m²
C44: Waist Slab of Flight | D44: 4 | E44: 0.95 | F44: 3 | H44: =F44*E44*D44 -> 11.4 | I44: m²
C46: Class IV (Internal)
C47: Living Room | D47: 12 | E47: 3.05 | F47: 3.75 | H47: =F47*E47*D47 -> 137.25 | I47: m²
C48: Skirting | D48: 12 | E48: 3.05 | F48: 3.75 | G48: 0.1 | H48: =F48*E48*D48*G48 -> 13.725 | I48: m²
...

Sheet Painting Estimate Colony F
A1: M E A S U R E M E N T S
A3: Name of Work :- | C3: M&R TO W/S/S AT NAGOTHANE INDUSTRIAL AREA… REPAIRING & PAITING OF STAFF QUARTERS IN WTP COLONY AT NAGOTHANE
A6: Name of Work :- | C6: M&R TO W/S/S AT NAGOTHANE INDUSTRIAL AREA... REPAIRING & PAINTING OF STAFF QUARTERS IN WTP COLONY AT NAGOTHANE
A9: Item No. | B9: Ref.to CSR | C9: Description of Item | D9: No. | E9: Length | F9: Breath | G9: Depth | H9: Quantity | I9: Unit | J9: Rate | K9: Amount
A10: 1 | B10: Gen/A/10 | C10: Open excavation for road works, side gutters
C11: For Plinth Protection Class III L/S & S/S | D11: 2 | E11: 16 | F11: 1.5 | G11: 0.5 | H11: =D11*E11*F11*G11 -> 24 | I11: m³
D12: 2 | E12: 15.5 | F12: 1.5 | G12: 0.5 | H12: =D12*E12*F12*G12 -> 23.25 | I12: m³
C13: Add extra for front side | D13: 2 | E13: 3 | F13: 1.5 | G13: 0.5 | H13: =D13*E13*F13*G13 -> 4.5 | I13: m³
C14: For Plinth Protection Class IV L/S & S/S | D14: 2 | E14: 21 | F14: 1.5 | G14: 0.5 | H14: =D14*E14*F14*G14 -> 31.5 | I14: m³
D15: 2 | E15: 7.5 | F15: 1.5 | G15: 0.5 | H15: =D15*E15*F15*G15 -> 11.25 | I15: m³
C16: Add extra for front side | D16: 2 | E16: 3 | F16: 1.5 | G16: 0.5 | H16: =D16*E16*F16*G16 -> 4.5 | I16: m³
F17: Total | H17: =SUM(H11:H16) -> 99 | I17: m³
F18: Say | H18: =ROUNDUP(H17,0) -> 99 | I18: m³ | J18: 150 | K18: =J18*H18 -> 14850
A19: 2 | B19: Gen/B/7 | C19: Removing tiled flooring in all types of tiling or flooring i.e. Shahabad, Kotah, Cement, ….. with all leads & lifts.
C20: For Plinth Protection Class III L/S & S/S | D20: 2 | E20: 16 | F20: 1.5 | H20: =F20*E20*D20 -> 48 | I20: m³
D21: 2 | E21: 15.5 | F21: 1.5 | H21: =F21*E21*D21 -> 46.5 | I21: m³
C22: For Plinth Protection Class IV L/S & S/S | D22: 2 | E22: 21 | F22: 1.5 | H22: =D22*E22*F22 -> 63 | I22: m²
D23: 2 | E23: 7.5 | F23: 1.5 | H23: =D23*E23*F23 -> 22.5 | I23: m²
G24: Total | H24: =SUM(H20:H23) -> 180 | I24: m² | J24: (I)
C25: Flooring
C26: Class III (Internal)
C27: Living Room | D27: 8 | E27: 3.05 | F27: 3.6 | H27: =F27*E27*D27 -> 87.84 | I27: m²
C28: Skirting | D28: 8 | E28: 3.05 | F28: 3.6 | G28: 0.1 | H28: =F28*E28*D28*G28 -> 8.784 | I28: m²
C29: Bed Room | D29: 8 | E29: 3.05 | F29: 3.05 | H29: =F29*E29*D29 -> 74.42 | I29: m²
C30: Skirting | D30: 8 | E30: 3.05 | F30: 3.05 | G30: 0.1 | H30: =F30*E30*D30*G30 -> 7.442 | I30: m²
C31: Kit.Room | D31: 8 | E31: 3.05 | F31: 2.12 | H31: =F31*E31*D31 -> 51.728 | I31: m²
C32: Skirting | D32: 8 | E32: 3.05 | F32: 2.12 | G32: 0.1 | H32: =F32*E32*D32*G32 -> 5.1728 | I32: m²
C33: Bath | D33: 8 | E33: 1.9 | F33: 1.07 | H33: =F33*E33*D33 -> 16.264 | I33: m²
C34: Removing Dado | D34: 8 | E34: 1.9 | F34: 1.07 | G34: 1.5 | H34: =F34*E34*D34*G34 -> 24.396 | I34: m²
C35: W.C. | D35: 8 | E35: 1.08 | F35: 0.95 | H35: =F35*E35*D35 -> 8.208 | I35: m²
C36: Removing Dado | D36: 8 | E36: 1.08 | F36: 0.95 | G36: 1.5 | H36: =F36*E36*D36*G36 -> 12.312 | I36: m²
C37: Passage | D37: 8 | E37: 3.05 | F37: 2.14 | H37: =F37*E37*D37 -> 52.216 | I37: m²
C38: Comman Passage @ Ground | D38: 1 | E38: 5.1 | F38: 2.15 | H38: =F38*E38*D38 -> 10.965 | I38: m²
C39: Comman Passage @ Ist Floor & IInd Floor | D39: 2 | E39: 2.5 | F39: 2.15 | H39: =F39*E39*D39 -> 10.75 | I39: m²
C40: Staircsae Head Room Slab | D40: 1 | E40: 5.2 | F40: 2.15 | H40: =F40*E40*D40 -> 11.18 | I40: m²
C41: Mid Landing | D41: 2 | E41: 2.15 | F41: 1.2 | H41: =F41*E41*D41 -> 5.16 | I41: m²
C42: Waist Slab of Flight | D42: 4 | E42: 0.95 | F42: 3 | H42: =F42*E42*D42 -> 11.4 | I42: m²
C44: Class IV (Internal)
C45: Living Room | D45: 12 | E45: 3.05 | F45: 3.75 | H45: =F45*E45*D45 -> 137.25 | I45: m²
C46: Skirting | D46: 12 | E46: 3.05 | F46: 3.75 | G46: 0.1 | H46: =F46*E46*D46*G46 -> 13.725 | I46: m²
...

Sheet Class IV 
A1: MAHARASHTRA INDUSTRIAL DEVELOPMENT CORPORATION
A2: ( A Government of Maharashtra Undertaking )
A4: Name of Work :- | C4: Nagothane Industrial Area ....M&R to W/S/S ... Repairs , Painting & Micellaneous work to Class-IV Staff Quarters at WTP Colony, Nagothane.
A7: Item No. | B7: Ref.to CSR | C7: Description of Item | D7: No. | E7: Length | F7: Breath | G7: Depth | H7: Quantity | I7: Unit | J7: Rate | K7: Amount
A8: 1 | B8: 21.02 | C8: Excavation for foundation in earth, soil of all types, sand, gravel and soft murum, including removing the excavated material up to a distance of 50 m. beyond the building area and stacking and spreading as directed, dewatering, preparing the bed for the foundation and necessary back filling, ramming, watering including shoring and strutting etc. complete. (Lift upto 1.5 m.) By Mechanical Means
C9: For Plinth Protection Class IV L/S & S/S | D9: 2 | E9: 21 | F9: 1.5 | G9: 0.5 | H9: =D9*E9*F9*G9 -> 31.5
D10: 2 | E10: 7.5 | F10: 1.5 | G10: 0.5 | H10: =D10*E10*F10*G10 -> 11.25
C11: Add extra for front side | D11: 2 | E11: 3 | F11: 1.5 | G11: 0.5 | H11: =D11*E11*F11*G11 -> 4.5
F12: Total | H12: =SUM(H9:H11) -> 47.25
G13: Say | H13: =ROUNDUP(H12,0) -> 48 | I13: m³ | J13: 207 | K13: =J13*H13 -> 9936
A15: =1+A8 -> 2 | B15: 32.33 | C15: Removing lime or cement plaster including disposing off the spoils as directed with all leads & lifts. Provision for painting.
B16: b) | C16: Class IV
C17: Ceiling
C18: Living Room | D18: 12 | E18: 3.05 | F18: 3.75 | H18: =F18*E18*D18 -> 137.25
C19: Kit.Room | D19: 12 | E19: 3.05 | F19: 3.05 | H19: =F19*E19*D19 -> 111.63
C20: Passage | D20: 12 | E20: 0.98 | F20: 2.52 | H20: =F20*E20*D20 -> 29.6352
C21: Bath | D21: 12 | E21: 1.22 | F21: 1.22 | H21: =F21*E21*D21 -> 17.8608
C22: W.C. | D22: 12 | E22: 0.95 | F22: 1.22 | H22: =F22*E22*D22 -> 13.908
C23: Comman Passage @ Ground | D23: 1 | E23: 5.307 | F23: 2.15 | H23: =F23*E23*D23 -> 11.41005
C24: Comman Passage @ Ist Floor & IIst Floor | D24: 2 | E24: 3.74 | F24: 2.15 | H24: =F24*E24*D24 -> 16.082
C25: Staircsae Head Room Slab | D25: 1 | E25: 2.15 | F25: 5.2 | H25: =F25*E25*D25 -> 11.18
C26: Mid Landing | D26: 3 | E26: 2.15 | F26: 1.2 | H26: =F26*E26*D26 -> 7.74
C27: Waist Slab of Flight | D27: 6 | E27: 0.95 | F27: 3 | H27: =F27*E27*D27 -> 17.1
F28: Total (A) | H28: =SUM(H18:H27) -> 373.79605
B29: d) | C29: Class IV (Internal)
C30: Walls
C31: Living Room | D31: 12x2 | E31: 3.05 | F31: 3.1 | H31: =F31*E31*8*2 -> 151.28
D32: 12x2 | E32: 3.75 | F32: 3.1 | H32: =F32*E32*8*2 -> 186
C33: Kit.Room | D33: 12x2 | E33: 3.05 | F33: 3.1 | H33: =F33*E33*8*2 -> 151.28
D34: 12x2 | E34: 3.35 | F34: 3.1 | H34: =F34*E34*8*2 -> 166.16
C35: Passage | D35: 12x2 | E35: 2.52 | F35: 3.1 | H35: =F35*E35*8*2 -> 124.992
D36: 12x2 | E36: 0.98 | F36: 3.1 | H36: =F36*E36*8*2 -> 48.608
C37: Bath | D37: 12x2 | E37: 1.22 | F37: 2.2 | H37: =F37*E37*8*2 -> 42.944
D38: 12x2 | E38: 1.22 | F38: 2.2 | H38: =F38*E38*8*2 -> 42.944
C39: W.C. | D39: 12x2 | E39: 1.22 | F39: 2.27 | H39: =F39*E39*8*2 -> 44.3104
D40: 12x2 | E40: 0.95 | F40: 2.27 | H40: =F40*E40*8*2 -> 34.504
C41: Comman Passage @ Ground, | D41: 1 | E41: 2.15 | F41: 3.05 | H41: =F41*E41*2*2 -> 26.23
D42: 1 | E42: 5.1 | F42: 3.05 | H42: =F42*E42*2*3 -> 93.33
C43: Comman Passage Ist,IInd & IIIrd Floor | D43: 3 | E43: 3.97 | F43: 2.15
D44: 3 | E44: 3.97 | F44: 2.15 | H44: =F44*E44*D44 -> 25.6065
...

Sheet FS
A1: MAHARASHTRA INDUSTRIAL DEVELOPMENT CORPORATION
A2: ( A Government of Maharashtra Undertaking )
A4: E S T I M A T E
A7: Name of work : | B7: Nagothane Industrial Area ....M&R to W/S/S ... Repairs , Painting & Micellaneous work to Class-IV Staff Quarters at WTP Colony, Nagothane.
A9: Estimated cost : | B9: Net Rs. | D9: =D60 -> 4966500
B10: Gross Rs.
A11: Ref. to Adm. Approval :
A13: Tech. Sanction : | B13: For Rs. | D13: Net.
B15: granted by
B16: Vide Register Item No.
B17: for the month of ____________ 2026 .
A19: Estimate prepared by : | B19: Name & Designation :
D21: Shri. Jadhav R.D
B22: Signature : | D22: Jn. Engr.
A25: Checked by : | B25: Name & Designation : | D25: Shri. Rahpade .V
D26: OSD
B27: Signature :
B29: Deputy Engineer | D29: Shri.Kumbhar S.A
D30: Dy. Engr.
B33: Executive Engineer | D33: Shri. Shelar V.P
D34: E. Engr.
B37: Superintending Engineer | D37: Shri. Rakshe S.L
D38: S. Engr.
B40: Chief Engineer
A45: Name of work : | B45: Nagothane Industrial Area ....M&R to W/S/S ... Repairs , Painting & Micellaneous work to Class-IV Staff Quarters at WTP Colony, Nagothane.
A48: Cost Estimate :
A50: Work Portion :- Class IV Qtrs | C50: Rs | D50: ='Class IV '!K362 -> 3958590.9
D51: =SUM(D50:D50) -> 3958590.9
A52: Testing | C52: Rs | D52: =QC!F14 -> 17790
D53: =SUM(D51:D52) -> 3976380.9
A54: Add 5% for Contingencies | D54: =D53*5% -> 198819.04
D55: =SUM(D53:D54) -> 4175199.9
A56: Add 18% for GST | D56: =D55*18% -> 751535.99
A57: Labour Insurance 1 % | D57: =D53*1% -> 39763.809
D58: =SUM(D55:D57) -> 4966499.7
B59: Total | D59: =D58 -> 4966499.7
B60: Say Net Amount | C60: Rs. | D60: =ROUNDUP(D59,0) -> 4966500 | F60: (N)
C66: Deputy Engineer & PA-I
C67: MIDC,DIVISION,ALIBAG.

Sheet QC
A1: MAHARASHTRA INDUSTRIAL DEVELOPMENT CORPORATION
A2: ( A Government of Maharashtra Undertaking )
A3: Name of Work :Nagothane Industrial Area ....M&R to W/S/S ... Repairs , Painting & Micellaneous work to Class-IV Staff Quarters at WTP Colony, Nagothane.
A4: MEASUREMENTS AND ABSTRACT
A5: Sub Estimate - III : Testing of Material
A7: Sr. No. | B7: Name of Test | C7: Testing Frequency | D7: Req. no.of Tests | E7: Rate / 1 Test | F7: Total QC Testing charges
A8: 1 | B8: BASIC TEST OF CEMENT : Standard Consistancy, Fineness, Specific Gravity, Setting Time ( Initial & Final ), Compressive Strength, Soundness | C8: 1 Test per 150 MT | D8: 1 | E8: 7540 | F8: =E8*D8 -> 7540 | M8: 52
A9: 2 | B9: BASIC TEST OF AGGREGATE : Sieve Analysis | C9: 1 Test per 200 Cum | D9: 1 | E9: 1380 | F9: =D9*E9 -> 1380
A10: 3 | B10: FINE AGGREGATE : Sieve Analysis,Silt & Clay Conten | C10: 1 Test per Source | D10: 1 | E10: 2760 | F10: =E10*D10 -> 2760
A11: 4 | B11: CONCRETE : Compressive Strength OF C.C. Cube (Set of 3 cubes). | C11: a) Upto 5 cum.-1 Set. b) 6 to 15 cum-2Sets c) 16 to 30 cum-3Sets. d) 31 to 50 cum-4Sets. e) 51 & above- 4Plus additional set for every additional 50 Cum
B12: M 15 | D12: 2 | E12: 1380 | F12: =E12*D12 -> 2760
A13: 5 | B13: Ceramic tile/ vetrified tile 6 set | C13: 2 Test per Source | D13: 2 | E13: 1675 | F13: =E13*D13 -> 3350
F14: =SUM(F8:F13) -> 17790
D18: Deputy Engineer & PA-I
D19: MIDC,DIVISION,ALIBAG.
